Workbook

Sheet Inventario
A1: env | B1: namespace | C1: providerEnv | D1: deployedName | E1: applicationName | F1: configName | G1: microserviceType | H1: image | I1: isFeature | J1: deploymentName | K1: helmChartVersion | L1: ownerEmail | M1: gitUrl | N1: microserviceVersion | O1: configVersion | P1: frameworkVersion | Q1: configUrl
A2: PRO | B2: ns-storage | C2: AWS | D2: ms-storage-ondemand | E2: ms-storage-ondemand | F2: ms-storage-ondemand-micros-app-configs | G2: p4ms | H2: artifactory.apps.devops.aws.bancsabadell.com/p4-virtual/p4des/ms-storage-ondemand:2.1.0 | I2: =FALSE() -> FALSE | J2: ms-storage-ondemand-p4ms | K2: p4ms-1.1.10 | L2: v888087@adgbs.com | M2: https://bitbucket.apps.devops.aws.bancsabadell.com/scm/p4des/ms-storage-ondemand.git | N2: 2.1.0 | O2: 3.0.0 | P2: 3.9.6 | Q2: https://kubernetes-dashboard.apps.pro.aws.bancsabadell.com/#/configmap/pro-ns-storage/ms-storage-ondemand-micros-app-configs?namespace=pro-ns-storage
A3: PRO | B3: ns-ai | C3: AWS | D3: ms-ai-nlp-engine | E3: ms-ai-nlp-engine | F3: ms-ai-nlp-engine-micros-py-configs | G3: p4mspy | H3: artifactory.apps.devops.aws.bancsabadell.com/p4-virtual/ms-ai-nlp-engine:1.0.7 | I3: =FALSE() -> FALSE | J3: ms-ai-nlp-engine-p4mspy | K3: p4mspy-0.0.11 | L3: mariano.carello@quant.global | M3: http://repos.bancsabadell.com/bitbucket/scm/ESSAB_P4_AI/ms-ai-nlp-engine.git | N3: 1.0.7 | O3: 1.0.6 | P3: null | Q3: https://kubernetes-dashboard.apps.pro.aws.bancsabadell.com/#/configmap/pro-ns-ai/ms-ai-nlp-engine-micros-py-configs?namespace=pro-ns-ai
A4: PRO | B4: ns-ai | C4: AWS | D4: ms-ai-audio-transcribe | E4: ms-ai-audio-transcribe | F4: ms-ai-audio-transcribe-micros-app-configs | G4: p4ms | H4: artifactory.apps.devops.aws.bancsabadell.com/p4-virtual/essab_p4_ai/ms-ai-audio-transcribe:4.3.1 | I4: =FALSE() -> FALSE | J4: ms-ai-audio-transcribe-p4ms | K4: p4ms-1.1.8 | L4: cnunez@paradigmadigital.com | M4: http://repos.bancsabadell.com/bitbucket/scm/ESSAB_P4_AI/ms-ai-audio-transcribe.git | N4: 4.3.1 | O4: 4.3.2 | P4: 3.7.0 | Q4: https://kubernetes-dashboard.apps.pro.aws.bancsabadell.com/#/configmap/pro-ns-ai/ms-ai-audio-transcribe-micros-app-configs?namespace=pro-ns-ai
A5: PRO | B5: ns-ai | C5: AWS | D5: ms-ai-derivation | E5: ms-ai-derivation | F5: ms-ai-derivation-micros-py-configs | G5: p4mspy | H5: artifactory.apps.devops.aws.bancsabadell.com/p4-virtual/ms-ai-derivation:1.0.7 | I5: =FALSE() -> FALSE | J5: ms-ai-derivation-p4mspy | K5: p4mspy-0.0.13 | L5: daniel.b.delgado@accenture.com | M5: http://repos.bancsabadell.com/bitbucket/scm/ES/ms-ai-derivation.git | N5: 1.0.7 | O5: 1.0.1 | P5: null | Q5: https://kubernetes-dashboard.apps.pro.aws.bancsabadell.com/#/configmap/pro-ns-ai/ms-ai-derivation-micros-py-configs?namespace=pro-ns-ai
A6: PRO | B6: ns-ai | C6: AWS | D6: ms-ai-subject-1 | E6: ms-ai-subject-1 | F6: ms-ai-subject-1-micros-py-configs | G6: p4mspy | H6: artifactory.apps.devops.aws.bancsabadell.com/p4-virtual/ms-ai-subject-1:1.0.1 | I6: =FALSE() -> FALSE | J6: ms-ai-subject-1-p4mspy | K6: p4mspy-0.0.7 | L6: ignacio.martin@accenture.com | M6: http://repos.bancsabadell.com/bitbucket/scm/ES/ms-ai-subject-1.git | N6: 1.0.1 | O6: 1.0.1 | P6: null | Q6: https://kubernetes-dashboard.apps.pro.aws.bancsabadell.com/#/configmap/pro-ns-ai/ms-ai-subject-1-micros-py-configs?namespace=pro-ns-ai
A7: PRO | B7: ns-ai | C7: AWS | D7: ms-ai-resolution | E7: ms-ai-resolution | F7: ms-ai-resolution-micros-py-configs | G7: p4mspy | H7: artifactory.apps.devops.aws.bancsabadell.com/p4-virtual/ms-ai-resolution:1.0.7 | I7: =FALSE() -> FALSE | J7: ms-ai-resolution-p4mspy | K7: p4mspy-0.0.8 | L7: daniel.b.delgado@accenture.com | M7: http://repos.bancsabadell.com/bitbucket/scm/ES/ms-ai-resolution.git | N7: 1.0.7 | O7: 1.0.1 | P7: null | Q7: https://kubernetes-dashboard.apps.pro.aws.bancsabadell.com/#/configmap/pro-ns-ai/ms-ai-resolution-micros-py-configs?namespace=pro-ns-ai
A8: PRO | B8: ns-ai | C8: AWS | D8: ms-ai-llm-text-engine | E8: ms-ai-llm-text-engine | F8: ms-ai-llm-text-engine-micros-py-configs | G8: p4mspy | H8: artifactory.apps.devops.aws.bancsabadell.com/p4-virtual/ms-ai-llm-text-engine:1.0.7 | I8: =FALSE() -> FALSE | J8: ms-ai-llm-text-engine-p4mspy | K8: p4mspy-0.0.11 | L8: j.e.martin@accenture.com | M8: http://repos.bancsabadell.com/bitbucket/scm/ESSAB_P4_AI/ms-ai-llm-text-engine.git | N8: 1.0.7 | O8: 1.0.6 | P8: null | Q8: https://kubernetes-dashboard.apps.pro.aws.bancsabadell.com/#/configmap/pro-ns-ai/ms-ai-llm-text-engine-micros-py-configs?namespace=pro-ns-ai
A9: PRO | B9: ns-ai | C9: AWS | D9: ms-ai-file-anonymizer | E9: ms-ai-file-anonymizer | F9: ms-ai-file-anonymizer-micros-py-configs | G9: p4mspy | H9: artifactory.apps.devops.aws.bancsabadell.com/p4-virtual/ms-ai-file-anonymizer:2.2.4 | I9: =FALSE() -> FALSE | J9: ms-ai-file-anonymizer-p4mspy | K9: p4mspy-0.0.15 | L9: s482870@adgbs.com | M9: http://repos.bancsabadell.com/bitbucket/scm/VMB/ms-ai-file-anonymizer.git | N9: 2.2.4 | O9: 2.2.4 | P9: null | Q9: https://kubernetes-dashboard.apps.pro.aws.bancsabadell.com/#/configmap/pro-ns-ai/ms-ai-file-anonymizer-micros-py-configs?namespace=pro-ns-ai
A10: PRO | B10: ns-ai | C10: AWS | D10: ms-ai-sentiment | E10: ms-ai-sentiment | F10: ms-ai-sentiment-micros-py-configs | G10: p4mspy | H10: artifactory.apps.devops.aws.bancsabadell.com/p4-virtual/ms-ai-sentiment:1.0.9 | I10: =FALSE() -> FALSE | J10: ms-ai-sentiment-p4mspy | K10: p4mspy-0.0.13 | L10: daniel.b.delgado@accenture.com | M10: http://repos.bancsabadell.com/bitbucket/scm/ES/ms-ai-sentiment.git | N10: 1.0.9 | O10: 1.0.1 | P10: null | Q10: https://kubernetes-dashboard.apps.pro.aws.bancsabadell.com/#/configmap/pro-ns-ai/ms-ai-sentiment-micros-py-configs?namespace=pro-ns-ai
A11: PRO | B11: ns-ai | C11: AWS | D11: ms-ai-conversation-processor | E11: ms-ai-conversation-processor | F11: ms-ai-conversation-processor-micros-py-configs | G11: p4mspy | H11: artifactory.apps.devops.aws.bancsabadell.com/p4-virtual/ms-ai-conversation-processor:2.0.1 | I11: =FALSE() -> FALSE | J11: ms-ai-conversation-processor-p4mspy | K11: p4mspy-0.0.13 | L11: j.e.martin@accenture.com | M11: http://repos.bancsabadell.com/bitbucket/scm/ES/ms-ai-conversation-processor.git | N11: 2.0.1 | O11: 2.0.1 | P11: null | Q11: https://kubernetes-dashboard.apps.pro.aws.bancsabadell.com/#/configmap/pro-ns-ai/ms-ai-conversation-processor-micros-py-configs?namespace=pro-ns-ai
A12: PRO | B12: ns-bff | C12: AWS | D12: ms-domain-selae-redsys | E12: ms-domain-selae-redsys | F12: ms-domain-selae-redsys-micros-app-configs | G12: p4ms | H12: artifactory.apps.devops.aws.bancsabadell.com/p4-virtual/mobi/ms-domain-selae-redsys:0.1.11 | I12: =FALSE() -> FALSE | J12: ms-domain-selae-redsys-p4ms | K12: p4ms-0.9.0 | L12: josep.itarte@gft.com | M12: http://repos.bancsabadell.com/bitbucket/scm/MOBI/ms-domain-selae-redsys.git | N12: 0.1.11 | O12: 0.1.3 | P12: 1.0.0 | Q12: https://kubernetes-dashboard.apps.pro.aws.bancsabadell.com/#/configmap/pro-ns-bff/ms-domain-selae-redsys-micros-app-configs?namespace=pro-ns-bff
A13: PRO | B13: ns-bff | C13: AWS | D13: ms-bff-information-spaces-v1 | E13: ms-bff-information-spaces-v1 | F13: ms-bff-information-spaces-v1-micros-app-configs | G13: p4ms | H13: artifactory.apps.devops.aws.bancsabadell.com/p4-virtual/mobi/ms-bff-information-spaces-v1:1.2.6 | I13: =FALSE() -> FALSE | J13: ms-bff-information-spaces-v1-p4ms | K13: p4ms-1.1.24 | L13: anabel.monserrat@gft.com | M13: http://repos.bancsabadell.com/bitbucket/scm/MOBI/ms-bff-information-spaces-v1.git | N13: 1.2.6 | O13: 1.1.2 | P13: 3.9.5 | Q13: https://kubernetes-dashboard.apps.pro.aws.bancsabadell.com/#/configmap/pro-ns-bff/ms-bff-information-spaces-v1-micros-app-configs?namespace=pro-ns-bff
... A141: PRO | B141: ns-sys | C141: AWS | D141: ms-sys-party-authentication-iam-v1 | E141: ms-sys-party-authentication-iam-v1 | F141: ms-sys-party-authentication-iam-v1-micros-app-configs | G141: p4ms | H141: artifactory.apps.devops.aws.bancsabadell.com/p4-virtual/p4cp/ms-sys-party-authentication-iam-v1:1.0.4 | I141: =FALSE() -> FALSE | J141: ms-sys-party-authentication-iam-v1-p4ms | K141: p4ms-1.1.24 | L141: etika.rastogi@accenture.com | M141: http://repos.bancsabadell.com/bitbucket/scm/p4cp/ms-sys-party-authentication-iam-v1.git | N141: 1.0.4 | O141: 1.0.0 | P141: 3.9.8 | Q141: https://kubernetes-dashboard.apps.pro.aws.bancsabadell.com/#/configmap/pro-ns-sys/ms-sys-party-authentication-iam-v1-micros-app-configs?namespace=pro-ns-sys
A142: PRO | B142: ns-sys | C142: AWS | D142: ms-sys-saml | E142: ms-sys-saml | F142: ms-sys-saml-micros-app-configs | G142: p4ms | H142: artifactory.apps.devops.aws.bancsabadell.com/p4-virtual/p4cp/ms-sys-saml:0.4.2 | I142: =FALSE() -> FALSE | J142: ms-sys-saml-p4ms | K142: p4ms-1.1.6 | L142: raul.castilla@alten.es | M142: http://repos.bancsabadell.com/bitbucket/scm/P4CP/ms-sys-saml.git | N142: 0.4.2 | P142: 1.6.0 | Q142: https://kubernetes-dashboard.apps.pro.aws.bancsabadell.com/#/configmap/pro-ns-sys/ms-sys-saml-micros-app-configs?namespace=pro-ns-sys
A143: PRO | B143: ns-sys | C143: AWS | D143: ms-sys-regulatory-and-legal-authority | E143: ms-sys-regulatory-and-legal-authority | F143: ms-sys-regulatory-and-legal-authority-micros-app-configs | G143: p4ms | H143: artifactory.apps.devops.aws.bancsabadell.com/p4-virtual/poojj/ms-sys-regulatory-and-legal-authority:1.0.13 | I143: =FALSE() -> FALSE | J143: ms-sys-regulatory-and-legal-authority-p4ms | K143: p4ms-1.1.6 | L143: 0901ProjectServiceGFT@bancsabadell.com | M143: http://repos.bancsabadell.com/bitbucket/scm/poojj/ms-sys-regulatory-and-legal-authority.git | N143: 1.0.13 | O143: 1.0.3 | P143: 1.4.1 | Q143: https://kubernetes-dashboard.apps.pro.aws.bancsabadell.com/#/configmap/pro-ns-sys/ms-sys-regulatory-and-legal-authority-micros-app-configs?namespace=pro-ns-sys
A144: PRO | B144: ns-sys | C144: AWS | D144: ms-sys-tasaciones-anonymizer-consumer | E144: ms-sys-tasaciones-anonymizer-consumer | F144: ms-sys-tasaciones-anonymizer-consumer-micros-app-configs | G144: p4ms | H144: artifactory.apps.devops.aws.bancsabadell.com/p4-virtual/p4cp/ms-sys-tasaciones-anonymizer-consumer:1.1.0 | I144: =FALSE() -> FALSE | J144: ms-sys-tasaciones-anonymizer-consumer-p4ms | K144: p4ms-1.1.24 | L144: etika.rastogi@accenture.com | M144: http://repos.bancsabadell.com/bitbucket/scm/P4CP/ms-sys-tasaciones-anonymizer-consumer.git | N144: 1.1.0 | O144: 1.0.7 | P144: 3.9.9 | Q144: https://kubernetes-dashboard.apps.pro.aws.bancsabadell.com/#/configmap/pro-ns-sys/ms-sys-tasaciones-anonymizer-consumer-micros-app-configs?namespace=pro-ns-sys
A145: PRO | B145: ns-sys | C145: AWS | D145: ms-sys-current-account-fp | E145: ms-sys-current-account-fp | F145: ms-sys-current-account-fp-micros-app-configs | G145: p4ms | H145: artifactory.apps.devops.aws.bancsabadell.com/p4-virtual/p4cp/ms-sys-current-account-fp:0.3.4 | I145: =FALSE() -> FALSE | J145: ms-sys-current-account-fp-p4ms | K145: p4ms-1.1.10 | L145: ddcp@gft.com | M145: http://repos.bancsabadell.com/bitbucket/scm/P4CP/ms-sys-current-account-fp.git | N145: 0.3.4 | O145: 1.0.4 | P145: 1.16.3 | Q145: https://kubernetes-dashboard.apps.pro.aws.bancsabadell.com/#/configmap/pro-ns-sys/ms-sys-current-account-fp-micros-app-configs?namespace=pro-ns-sys
A146: PRO | B146: ns-sys | C146: AWS | D146: ms-sys-payment-instruction-ip | E146: ms-sys-payment-instruction-ip | F146: ms-sys-payment-instruction-ip-micros-app-configs | G146: p4ms | H146: artifactory.apps.devops.aws.bancsabadell.com/p4-virtual/p4cp/ms-sys-payment-instruction-ip:2.1.2 | I146: =FALSE() -> FALSE | J146: ms-sys-payment-instruction-ip-p4ms | K146: p4ms-1.1.8 | L146: y.chawla@accenture.com | M146: http://repos.bancsabadell.com/bitbucket/scm/P4CP/ms-sys-payment-instruction-ip.git | N146: 2.1.2 | O146: 0.0.3 | P146: 1.11.0 | Q146: https://kubernetes-dashboard.apps.pro.aws.bancsabadell.com/#/configmap/pro-ns-sys/ms-sys-payment-instruction-ip-micros-app-configs?namespace=pro-ns-sys
A147: PRO | B147: ns-sys | C147: AWS | D147: ms-sys-customer-products-and-services-sp-v1 | E147: ms-sys-customer-products-and-services-sp-v1 | F147: ms-sys-customer-products-and-services-sp-v1-micros-app-configs | G147: p4ms | H147: artifactory.apps.devops.aws.bancsabadell.com/p4-virtual/p4cp/ms-sys-customer-products-and-services-sp-v1:2.0.5 | I147: =FALSE() -> FALSE | J147: ms-sys-customer-products-and-services-sp-v1-p4ms | K147: p4ms-0.15.3 | L147: smorenoe@minsait.com | M147: http://repos.bancsabadell.com/bitbucket/scm/p4cp/ms-sys-customer-products-and-services-sp-v1.git | N147: 2.0.5 | O147: 1.0.2 | P147: 1.7.0 | Q147: https://kubernetes-dashboard.apps.pro.aws.bancsabadell.com/#/configmap/pro-ns-sys/ms-sys-customer-products-and-services-sp-v1-micros-app-configs?namespace=pro-ns-sys
A148: PRO | B148: ns-sys | C148: AWS | D148: ms-sys-cards-dds-v1 | E148: ms-sys-cards-dds-v1 | F148: ms-sys-cards-dds-v1-micros-app-configs | G148: p4ms | H148: artifactory.apps.devops.aws.bancsabadell.com/p4-virtual/mobi/ms-sys-cards-dds-v1:1.1.71 | I148: =FALSE() -> FALSE | J148: ms-sys-cards-dds-v1-p4ms | K148: p4ms-1.1.26 | L148: fjtaboada@minsait.com | M148: http://repos.bancsabadell.com/bitbucket/scm/mobi/ms-sys-cards-dds-v1.git | N148: 1.1.71 | O148: 1.3.19 | P148: 3.9.12 | Q148: https://kubernetes-dashboard.apps.pro.aws.bancsabadell.com/#/configmap/pro-ns-sys/ms-sys-cards-dds-v1-micros-app-configs?namespace=pro-ns-sys
A149: PRO | B149: ns-sys | C149: AWS | D149: ms-sys-party-reference-data-pe-v3 | E149: ms-sys-party-reference-data-pe-v3 | F149: ms-sys-party-reference-data-pe-v3-micros-app-configs | G149: p4ms | H149: artifactory.apps.devops.aws.bancsabadell.com/p4-virtual/mobi/ms-sys-party-reference-data-pe-v3:1.12.4 | I149: =FALSE() -> FALSE | J149: ms-sys-party-reference-data-pe-v3-p4ms | K149: p4ms-1.1.19 | L149: devops@devops.com | M149: http://repos.bancsabadell.com/bitbucket/scm/MOBI/ms-sys-party-reference-data-pe-v3.git | N149: 1.12.4 | O149: 1.10.4 | P149: 1.16.3 | Q149: https://kubernetes-dashboard.apps.pro.aws.bancsabadell.com/#/configmap/pro-ns-sys/ms-sys-party-reference-data-pe-v3-micros-app-configs?namespace=pro-ns-sys
A150: PRO | B150: ns-sys | C150: AWS | D150: ms-sys-factoring-system-fa-v1 | E150: ms-sys-factoring-system-fa-v1 | F150: ms-sys-factoring-system-fa-v1-micros-app-configs | G150: p4ms | H150: artifactory.apps.devops.aws.bancsabadell.com/p4-virtual/p4cp/ms-sys-factoring-system-fa-v1:1.1.0 | I150: =FALSE() -> FALSE | J150: ms-sys-factoring-system-fa-v1-p4ms | K150: p4ms-1.1.10 | L150: aayush.sagar@accenture.com | M150: http://repos.bancsabadell.com/bitbucket/scm/P4cp/ms-sys-factoring-system-fa-v1.git | N150: 1.1.0 | O150: 1.0.6 | P150: 3.7.2 | Q150: https://kubernetes-dashboard.apps.pro.aws.bancsabadell.com/#/configmap/pro-ns-sys/ms-sys-factoring-system-fa-v1-micros-app-configs?namespace=pro-ns-sys
A151: PRO | B151: ns-sys | C151: AWS | D151: ms-sys-adobe-delete-entity | E151: ms-sys-adobe-delete-entity | F151: ms-sys-adobe-delete-entity-micros-app-configs | G151: p4ms | H151: artifactory.apps.devops.aws.bancsabadell.com/p4-virtual/p4cp/ms-sys-adobe-delete-entity:1.0.3 | I151: =FALSE() -> FALSE | J151: ms-sys-adobe-delete-entity-p4ms | K151: p4ms-1.1.19 | L151: Daniel.Gimenez.Verdugo@everis.com | M151: http://repos.bancsabadell.com/bitbucket/scm/p4cp/ms-sys-adobe-delete-entity.git | N151: 1.0.3 | O151: 0.0.1 | P151: 3.9.5 | Q151: https://kubernetes-dashboard.apps.pro.aws.bancsabadell.com/#/configmap/pro-ns-sys/ms-sys-adobe-delete-entity-micros-app-configs?namespace=pro-ns-sys
A152: PRO | B152: ns-sys | C152: AWS | D152: ms-sys-onboarding-process | E152: ms-sys-onboarding-process | F152: ms-sys-onboarding-process-micros-app-configs | G152: p4ms | H152: artifactory.apps.devops.aws.bancsabadell.com/p4-virtual/p4cp/ms-sys-onboarding-process:0.13.0 | I152: =FALSE() -> FALSE | J152: ms-sys-onboarding-process-p4ms | K152: p4ms-0.15.1 | L152: apardoba@everis.com | M152: http://repos.bancsabadell.com/bitbucket/scm/P4CP/ms-sys-onboarding-process.git | N152: 0.13.0 | O152: 0.6.8 | P152: 1.11.0 | Q152: https://kubernetes-dashboard.apps.pro.aws.bancsabadell.com/#/configmap/pro-ns-sys/ms-sys-onboarding-process-micros-app-configs?namespace=pro-ns-sys
A153: PRO | B153: ns-sys | C153: AWS | D153: ms-sys-fraud | E153: ms-sys-fraud | F153: ms-sys-fraud-micros-app-configs | G153: p4ms | H153: artifactory.apps.devops.aws.bancsabadell.com/p4-virtual/p4des/ms-sys-fraud:1.3.1 | I153: =FALSE() -> FALSE | J153: ms-sys-fraud-p4ms | K153: p4ms-1.1.24 | L153: alfredo.miguel.estevez.mendez@nttdata.com | M153: https://bitbucket.apps.devops.aws.bancsabadell.com/scm/P4DES/ms-sys-fraud.git | N153: 1.3.1 | O153: 1.0.14 | P153: 3.9.13 | Q153: https://kubernetes-dashboard.apps.pro.aws.bancsabadell.com/#/configmap/pro-ns-sys/ms-sys-fraud-micros-app-configs?namespace=pro-ns-sys
A154: PRO | B154: ns-sys | C154: AWS | D154: ms-sys-customer-relationship-management-scf | E154: ms-sys-customer-relationship-management-scf | F154: ms-sys-customer-relationship-management-scf-micros-app-configs | G154: p4ms | H154: artifactory.apps.devops.aws.bancsabadell.com/p4-virtual/p4cp/ms-sys-customer-relationship-management-scf:1.0.18 | I154: =FALSE() -> FALSE | J154: ms-sys-customer-relationship-management-scf-p4ms | K154: p4ms-1.1.8 | L154: BancSabadell.JavaFactory@accenture.com | M154: http://repos.bancsabadell.com/bitbucket/scm/p4cp/ms-sys-customer-relationship-management-scf.git | N154: 1.0.18 | O154: 1.0.6 | P154: 1.16.3 | Q154: https://kubernetes-dashboard.apps.pro.aws.bancsabadell.com/#/configmap/pro-ns-sys/ms-sys-customer-relationship-management-scf-micros-app-configs?namespace=pro-ns-sys
... A438: PRO | B438: ns-baas | C438: AWS | D438: ms-baas-ccf-v2 | E438: ms-baas-ccf-v2 | F438: ms-baas-ccf-v2-micros-app-configs | G438: p4ms | H438: artifactory.apps.devops.aws.bancsabadell.com/p4-virtual/p4cp/ms-baas-ccf-v2:1.1.0 | I438: =FALSE() -> FALSE | J438: ms-baas-ccf-v2-p4ms | K438: p4ms-1.1.10 | L438: umesh.kumar.singhal@accenture.com | M438: http://repos.bancsabadell.com/bitbucket/scm/p4cp/ms-baas-ccf-v2.git | N438: 1.1.0 | O438: 1.1.5 | P438: 1.15.0 | Q438: https://kubernetes-dashboard.apps.pro.aws.bancsabadell.com/#/configmap/pro-ns-baas/ms-baas-ccf-v2-micros-app-configs?namespace=pro-ns-baas

Sheet Cruce
A1: Micros | B1: deployed in PRO | C1: version config | D1: repo micro | E1: repo config | F1: branch
A2: ms-baas-consumer-loan-v1 | B2: =ISNUMBER(MATCH(A2,Inventario!D:D, 0)) -> TRUE | C2: =IFERROR(INDEX(Inventario!O:O, MATCH(A2,Inventario!D:D, 0)), "") -> 1.3.3 | D2: =IFERROR(INDEX(Inventario!M:M, MATCH(A2, Inventario!D:D, 0)), "") -> http://repos.bancsabadell.com/bitbucket/scm/P4CP/ms-baas-consumer-loan-v1.git | E2: =SUBSTITUTE(D2, ".git", "-conf/browse") -> http://repos.bancsabadell.com/bitbucket/scm/P4CP/ms-baas-consumer-loan-v1-conf/browse | F2: =CONCATENATE("release/",C2) -> release/1.3.3
A3: ms-batch-sinfonia-processor | B3: =ISNUMBER(MATCH(A3,Inventario!D:D, 0)) -> 1 | C3: =IFERROR(INDEX(Inventario!O:O, MATCH(A3,Inventario!D:D, 0)), "") -> 1.0.7 | D3: =IFERROR(INDEX(Inventario!M:M, MATCH(A3, Inventario!D:D, 0)), "") -> http://repos.bancsabadell.com/bitbucket/scm/p4cp/ms-batch-sinfonia-processor.git | E3: =SUBSTITUTE(D3, ".git", "-conf/browse") -> http://repos.bancsabadell.com/bitbucket/scm/p4cp/ms-batch-sinfonia-processor-conf/browse | F3: =CONCATENATE("release/",C3) -> release/1.0.7
A4: ms-baas-mortgage-loan-v1 | B4: =ISNUMBER(MATCH(A4,Inventario!D:D, 0)) -> 1 | C4: =IFERROR(INDEX(Inventario!O:O, MATCH(A4,Inventario!D:D, 0)), "") -> 1.1.4 | D4: =IFERROR(INDEX(Inventario!M:M, MATCH(A4, Inventario!D:D, 0)), "") -> http://repos.bancsabadell.com/bitbucket/scm/P4CP/ms-baas-mortgage-loan-v1.git | E4: =SUBSTITUTE(D4, ".git", "-conf/browse") -> http://repos.bancsabadell.com/bitbucket/scm/P4CP/ms-baas-mortgage-loan-v1-conf/browse | F4: =CONCATENATE("release/",C4) -> release/1.1.4
A5: ms-baas-special-pricing-conditions | B5: =ISNUMBER(MATCH(A5,Inventario!D:D, 0)) -> 1 | C5: =IFERROR(INDEX(Inventario!O:O, MATCH(A5,Inventario!D:D, 0)), "") -> 0.8.19 | D5: =IFERROR(INDEX(Inventario!M:M, MATCH(A5, Inventario!D:D, 0)), "") -> http://repos.bancsabadell.com/bitbucket/scm/JUST_RAROC/ms-baas-special-pricing-conditions.git | E5: =SUBSTITUTE(D5, ".git", "-conf/browse") -> http://repos.bancsabadell.com/bitbucket/scm/JUST_RAROC/ms-baas-special-pricing-conditions-conf/browse | F5: =CONCATENATE("release/",C5) -> release/0.8.19
A6: ms-baas-credit-facility-online-pr | B6: =ISNUMBER(MATCH(A6,Inventario!D:D, 0)) -> 1 | C6: =IFERROR(INDEX(Inventario!O:O, MATCH(A6,Inventario!D:D, 0)), "") -> 1.0.6 | D6: =IFERROR(INDEX(Inventario!M:M, MATCH(A6, Inventario!D:D, 0)), "") -> http://repos.bancsabadell.com/bitbucket/scm/P4CP/ms-baas-credit-facility-online-pr.git | E6: =SUBSTITUTE(D6, ".git", "-conf/browse") -> http://repos.bancsabadell.com/bitbucket/scm/P4CP/ms-baas-credit-facility-online-pr-conf/browse | F6: =CONCATENATE("release/",C6) -> release/1.0.6
A7: ms-sys-credit-facility-online-pr | B7: =ISNUMBER(MATCH(A7,Inventario!D:D, 0)) -> 1 | C7: =IFERROR(INDEX(Inventario!O:O, MATCH(A7,Inventario!D:D, 0)), "") -> 1.0.2 | D7: =IFERROR(INDEX(Inventario!M:M, MATCH(A7, Inventario!D:D, 0)), "") -> http://repos.bancsabadell.com/bitbucket/scm/P4CP/ms-sys-credit-facility-online-pr.git | E7: =SUBSTITUTE(D7, ".git", "-conf/browse") -> http://repos.bancsabadell.com/bitbucket/scm/P4CP/ms-sys-credit-facility-online-pr-conf/browse | F7: =CONCATENATE("release/",C7) -> release/1.0.2
A8: ms-baas-scf-packaging | B8: =ISNUMBER(MATCH(A8,Inventario!D:D, 0)) -> 1 | C8: =IFERROR(INDEX(Inventario!O:O, MATCH(A8,Inventario!D:D, 0)), "") -> 1.0.6 | D8: =IFERROR(INDEX(Inventario!M:M, MATCH(A8, Inventario!D:D, 0)), "") -> http://repos.bancsabadell.com/bitbucket/scm/p4cp/ms-baas-scf-packaging.git | E8: =SUBSTITUTE(D8, ".git", "-conf/browse") -> http://repos.bancsabadell.com/bitbucket/scm/p4cp/ms-baas-scf-packaging-conf/browse | F8: =CONCATENATE("release/",C8) -> release/1.0.6
A9: ms-sys-card-terminal-operation-ps | B9: =ISNUMBER(MATCH(A9,Inventario!D:D, 0)) -> 1 | C9: =IFERROR(INDEX(Inventario!O:O, MATCH(A9,Inventario!D:D, 0)), "") -> 1.0.2 | D9: =IFERROR(INDEX(Inventario!M:M, MATCH(A9, Inventario!D:D, 0)), "") -> http://repos.bancsabadell.com/bitbucket/scm/P4CP/ms-sys-card-terminal-operation-ps.git | E9: =SUBSTITUTE(D9, ".git", "-conf/browse") -> http://repos.bancsabadell.com/bitbucket/scm/P4CP/ms-sys-card-terminal-operation-ps-conf/browse | F9: =CONCATENATE("release/",C9) -> release/1.0.2
A10: ms-sys-customer-campaign-execution-system-kx | B10: =ISNUMBER(MATCH(A10,Inventario!D:D, 0)) -> 1 | C10: =IFERROR(INDEX(Inventario!O:O, MATCH(A10,Inventario!D:D, 0)), "") -> 1.0.2 | D10: =IFERROR(INDEX(Inventario!M:M, MATCH(A10, Inventario!D:D, 0)), "") -> http://repos.bancsabadell.com/bitbucket/scm/P4CP/ms-sys-customer-campaign-execution-system-kx.git | E10: =SUBSTITUTE(D10, ".git", "-conf/browse") -> http://repos.bancsabadell.com/bitbucket/scm/P4CP/ms-sys-customer-campaign-execution-system-kx-conf/browse | F10: =CONCATENATE("release/",C10) -> release/1.0.2
A11: ms-baas-factoring-v1 | B11: =ISNUMBER(MATCH(A11,Inventario!D:D, 0)) -> 1 | C11: =IFERROR(INDEX(Inventario!O:O, MATCH(A11,Inventario!D:D, 0)), "") -> 1.0.6 | D11: =IFERROR(INDEX(Inventario!M:M, MATCH(A11, Inventario!D:D, 0)), "") -> http://repos.bancsabadell.com/bitbucket/scm/P4cp/ms-baas-factoring-v1.git | E11: =SUBSTITUTE(D11, ".git", "-conf/browse") -> http://repos.bancsabadell.com/bitbucket/scm/P4cp/ms-baas-factoring-v1-conf/browse | F11: =CONCATENATE("release/",C11) -> release/1.0.6
A12: ms-sys-factoring-system-fa-v1 | B12: =ISNUMBER(MATCH(A12,Inventario!D:D, 0)) -> 1 | C12: =IFERROR(INDEX(Inventario!O:O, MATCH(A12,Inventario!D:D, 0)), "") -> 1.0.6 | D12: =IFERROR(INDEX(Inventario!M:M, MATCH(A12, Inventario!D:D, 0)), "") -> http://repos.bancsabadell.com/bitbucket/scm/P4cp/ms-sys-factoring-system-fa-v1.git | E12: =SUBSTITUTE(D12, ".git", "-conf/browse") -> http://repos.bancsabadell.com/bitbucket/scm/P4cp/ms-sys-factoring-system-fa-v1-conf/browse | F12: =CONCATENATE("release/",C12) -> release/1.0.6
A13: ms-baas-confirming-v1 | B13: =ISNUMBER(MATCH(A13,Inventario!D:D, 0)) -> 1 | C13: =IFERROR(INDEX(Inventario!O:O, MATCH(A13,Inventario!D:D, 0)), "") -> 1.0.4 | D13: =IFERROR(INDEX(Inventario!M:M, MATCH(A13, Inventario!D:D, 0)), "") -> http://repos.bancsabadell.com/bitbucket/scm/P4CP/ms-baas-confirming-v1.git | E13: =SUBSTITUTE(D13, ".git", "-conf/browse") -> http://repos.bancsabadell.com/bitbucket/scm/P4CP/ms-baas-confirming-v1-conf/browse | F13: =CONCATENATE("release/",C13) -> release/1.0.4
... A35: ms-baas-position-keeping-extended-v1 | B35: =ISNUMBER(MATCH(A35,Inventario!D:D, 0)) -> 1 | C35: =IFERROR(INDEX(Inventario!O:O, MATCH(A35,Inventario!D:D, 0)), "") -> 2.0.0 | D35: =IFERROR(INDEX(Inventario!M:M, MATCH(A35, Inventario!D:D, 0)), "") -> http://repos.bancsabadell.com/bitbucket/scm/MOBI/ms-baas-position-keeping-extended-v1.git | E35: =SUBSTITUTE(D35, ".git", "-conf/browse") -> http://repos.bancsabadell.com/bitbucket/scm/MOBI/ms-baas-position-keeping-extended-v1-conf/browse | F35: =CONCATENATE("release/",C35) -> release/2.0.0
A36: ms-baas-product-matching-baas-v1 | B36: =ISNUMBER(MATCH(A36,Inventario!D:D, 0)) -> 0 | C36: =IFERROR(INDEX(Inventario!O:O, MATCH(A36,Inventario!D:D, 0)), "") | D36: =IFERROR(INDEX(Inventario!M:M, MATCH(A36, Inventario!D:D, 0)), "") | E36: =SUBSTITUTE(D36, ".git", "-conf")
A37: ms-sys-notifications | B37: =ISNUMBER(MATCH(A37,Inventario!D:D, 0)) -> 1 | C37: =IFERROR(INDEX(Inventario!O:O, MATCH(A37,Inventario!D:D, 0)), "") -> 1.5.5 | D37: =IFERROR(INDEX(Inventario!M:M, MATCH(A37, Inventario!D:D, 0)), "") -> https://bitbucket.apps.devops.aws.bancsabadell.com/scm/p4des/ms-sys-notifications.git | E37: =SUBSTITUTE(D37, ".git", "-conf/browse") -> https://bitbucket.apps.devops.aws.bancsabadell.com/scm/p4des/ms-sys-notifications-conf/browse | F37: =CONCATENATE("release/",C37) -> release/1.5.5
A38: ms-sys-notifications-hub-email-sender | B38: =ISNUMBER(MATCH(A38,Inventario!D:D, 0)) -> 1 | C38: =IFERROR(INDEX(Inventario!O:O, MATCH(A38,Inventario!D:D, 0)), "") -> 1.0.2 | D38: =IFERROR(INDEX(Inventario!M:M, MATCH(A38, Inventario!D:D, 0)), "") -> https://bitbucket.apps.devops.aws.bancsabadell.com/scm/p4des/ms-sys-notifications-hub-email-sender.git | E38: =SUBSTITUTE(D38, ".git", "-conf/browse") -> https://bitbucket.apps.devops.aws.bancsabadell.com/scm/p4des/ms-sys-notifications-hub-email-sender-conf/browse | F38: =CONCATENATE("release/",C38) -> release/1.0.2
A39: ms-baas-correspondence-v2 | B39: =ISNUMBER(MATCH(A39,Inventario!D:D, 0)) -> 1 | C39: =IFERROR(INDEX(Inventario!O:O, MATCH(A39,Inventario!D:D, 0)), "") -> 1.0.6 | D39: =IFERROR(INDEX(Inventario!M:M, MATCH(A39, Inventario!D:D, 0)), "") -> http://repos.bancsabadell.com/bitbucket/scm/p4cp/ms-baas-correspondence-v2.git | E39: =SUBSTITUTE(D39, ".git", "-conf/browse") -> http://repos.bancsabadell.com/bitbucket/scm/p4cp/ms-baas-correspondence-v2-conf/browse | F39: =CONCATENATE("release/",C39) -> release/1.0.6
A40: ms-sys-correspondence-ia | B40: =ISNUMBER(MATCH(A40,Inventario!D:D, 0)) -> 1 | C40: =IFERROR(INDEX(Inventario!O:O, MATCH(A40,Inventario!D:D, 0)), "") -> 1.0.9 | D40: =IFERROR(INDEX(Inventario!M:M, MATCH(A40, Inventario!D:D, 0)), "") -> http://repos.bancsabadell.com/bitbucket/scm/p4cp/ms-sys-correspondence-ia.git | E40: =SUBSTITUTE(D40, ".git", "-conf/browse") -> http://repos.bancsabadell.com/bitbucket/scm/p4cp/ms-sys-correspondence-ia-conf/browse | F40: =CONCATENATE("release/",C40) -> release/1.0.9
A41: ms-baas-correspondence-v3 | B41: =ISNUMBER(MATCH(A41,Inventario!D:D, 0)) -> 1 | C41: =IFERROR(INDEX(Inventario!O:O, MATCH(A41,Inventario!D:D, 0)), "") -> 1.0.7 | D41: =IFERROR(INDEX(Inventario!M:M, MATCH(A41, Inventario!D:D, 0)), "") -> http://repos.bancsabadell.com/bitbucket/scm/p4cp/ms-baas-correspondence-v3.git | E41: =SUBSTITUTE(D41, ".git", "-conf/browse") -> http://repos.bancsabadell.com/bitbucket/scm/p4cp/ms-baas-correspondence-v3-conf/browse | F41: =CONCATENATE("release/",C41) -> release/1.0.7
A42: ms-sys-correspondence-ia-v2 | B42: =ISNUMBER(MATCH(A42,Inventario!D:D, 0)) -> 1 | C42: =IFERROR(INDEX(Inventario!O:O, MATCH(A42,Inventario!D:D, 0)), "") -> 1.0.6 | D42: =IFERROR(INDEX(Inventario!M:M, MATCH(A42, Inventario!D:D, 0)), "") -> http://repos.bancsabadell.com/bitbucket/scm/P4CP/ms-sys-correspondence-ia-v2.git | E42: =SUBSTITUTE(D42, ".git", "-conf/browse") -> http://repos.bancsabadell.com/bitbucket/scm/P4CP/ms-sys-correspondence-ia-v2-conf/browse | F42: =CONCATENATE("release/",C42) -> release/1.0.6
A43: ms-baas-servicing-order-v1 | B43: =ISNUMBER(MATCH(A43,Inventario!D:D, 0)) -> 1 | C43: =IFERROR(INDEX(Inventario!O:O, MATCH(A43,Inventario!D:D, 0)), "") -> 0.1.6 | D43: =IFERROR(INDEX(Inventario!M:M, MATCH(A43, Inventario!D:D, 0)), "") -> http://repos.bancsabadell.com/bitbucket/scm/p4cp/ms-baas-servicing-order-v1.git | E43: =SUBSTITUTE(D43, ".git", "-conf/browse") -> http://repos.bancsabadell.com/bitbucket/scm/p4cp/ms-baas-servicing-order-v1-conf/browse | F43: =CONCATENATE("release/",C43) -> release/0.1.6
A44: ms-sys-servicing-order-gt-v1 | B44: =ISNUMBER(MATCH(A44,Inventario!D:D, 0)) -> 1 | C44: =IFERROR(INDEX(Inventario!O:O, MATCH(A44,Inventario!D:D, 0)), "") -> 0.1.6 | D44: =IFERROR(INDEX(Inventario!M:M, MATCH(A44, Inventario!D:D, 0)), "") -> http://repos.bancsabadell.com/bitbucket/scm/p4cp/ms-sys-servicing-order-gt-v1.git | E44: =SUBSTITUTE(D44, ".git", "-conf/browse") -> http://repos.bancsabadell.com/bitbucket/scm/p4cp/ms-sys-servicing-order-gt-v1-conf/browse | F44: =CONCATENATE("release/",C44) -> release/0.1.6
A45: ms-baas-desktop-notifications | B45: =ISNUMBER(MATCH(A45,Inventario!D:D, 0)) -> 1 | C45: =IFERROR(INDEX(Inventario!O:O, MATCH(A45,Inventario!D:D, 0)), "") -> 1.0.8 | D45: =IFERROR(INDEX(Inventario!M:M, MATCH(A45, Inventario!D:D, 0)), "") -> http://repos.bancsabadell.com/bitbucket/scm/p4notifications/ms-baas-desktop-notifications.git | E45: =SUBSTITUTE(D45, ".git", "-conf/browse") -> http://repos.bancsabadell.com/bitbucket/scm/p4notifications/ms-baas-desktop-notifications-conf/browse | F45: =CONCATENATE("release/",C45) -> release/1.0.8
A46: ms-sys-party-routing-profile-aa | B46: =ISNUMBER(MATCH(A46,Inventario!D:D, 0)) -> 1 | C46: =IFERROR(INDEX(Inventario!O:O, MATCH(A46,Inventario!D:D, 0)), "") -> 0.3.3 | D46: =IFERROR(INDEX(Inventario!M:M, MATCH(A46, Inventario!D:D, 0)), "") -> http://repos.bancsabadell.com/bitbucket/scm/MOBI/ms-sys-party-routing-profile-aa.git | E46: =SUBSTITUTE(D46, ".git", "-conf/browse") -> http://repos.bancsabadell.com/bitbucket/scm/MOBI/ms-sys-party-routing-profile-aa-conf/browse | F46: =CONCATENATE("release/",C46) -> release/0.3.3
A47: ms-bff-tjmovilpinrecovery | B47: =ISNUMBER(MATCH(A47,Inventario!D:D, 0)) -> 1 | C47: =IFERROR(INDEX(Inventario!O:O, MATCH(A47,Inventario!D:D, 0)), "") -> 0.1.6 | D47: =IFERROR(INDEX(Inventario!M:M, MATCH(A47, Inventario!D:D, 0)), "") -> http://repos.bancsabadell.com/bitbucket/scm/P4CP/ms-bff-tjmovilpinrecovery.git | E47: =SUBSTITUTE(D47, ".git", "-conf/browse") -> http://repos.bancsabadell.com/bitbucket/scm/P4CP/ms-bff-tjmovilpinrecovery-conf/browse | F47: =CONCATENATE("release/",C47) -> release/0.1.6
A48: ms-bff-party-reference-data-directory-v2 | B48: =ISNUMBER(MATCH(A48,Inventario!D:D, 0)) -> 1 | C48: =IFERROR(INDEX(Inventario!O:O, MATCH(A48,Inventario!D:D, 0)), "") -> 1.1.2 | D48: =IFERROR(INDEX(Inventario!M:M, MATCH(A48, Inventario!D:D, 0)), "") -> http://repos.bancsabadell.com/bitbucket/scm/MOBI/ms-bff-party-reference-data-directory-v2.git | E48: =SUBSTITUTE(D48, ".git", "-conf/browse") -> http://repos.bancsabadell.com/bitbucket/scm/MOBI/ms-bff-party-reference-data-directory-v2-conf/browse | F48: =CONCATENATE("release/",C48) -> release/1.1.2
... A106: ms-sys-customer-offer-pz | B106: =ISNUMBER(MATCH(A106,Inventario!D:D, 0)) -> 1 | C106: =IFERROR(INDEX(Inventario!O:O, MATCH(A106,Inventario!D:D, 0)), "") -> 1.0.1 | D106: =IFERROR(INDEX(Inventario!M:M, MATCH(A106, Inventario!D:D, 0)), "") -> http://repos.bancsabadell.com/bitbucket/scm/POOJJ/ms-sys-customer-offer-pz.git | E106: =SUBSTITUTE(D106, ".git", "-conf/browse") -> http://repos.bancsabadell.com/bitbucket/scm/POOJJ/ms-sys-customer-offer-pz-conf/browse | F106: =CONCATENATE("release/",C106) -> release/1.0.1
A107: ms-sys-informa-docu-pe | B107: =ISNUMBER(MATCH(A107,Inventario!D:D, 0)) -> 0 | C107: =IFERROR(INDEX(Inventario!O:O, MATCH(A107,Inventario!D:D, 0)), "") | D107: =IFERROR(INDEX(Inventario!M:M, MATCH(A107, Inventario!D:D, 0)), "") | E107: =SUBSTITUTE(D107, ".git", "-conf")
A108: ms-sys-legal-entity-directory-ee-v1 | B108: =ISNUMBER(MATCH(A108,Inventario!D:D, 0)) -> 1 | C108: =IFERROR(INDEX(Inventario!O:O, MATCH(A108,Inventario!D:D, 0)), "") -> 0.0.2 | D108: =IFERROR(INDEX(Inventario!M:M, MATCH(A108, Inventario!D:D, 0)), "") -> http://repos.bancsabadell.com/bitbucket/scm/P4CP/ms-sys-legal-entity-directory-ee-v1.git | E108: =SUBSTITUTE(D108, ".git", "-conf/browse") -> http://repos.bancsabadell.com/bitbucket/scm/P4CP/ms-sys-legal-entity-directory-ee-v1-conf/browse | F108: =CONCATENATE("release/",C108) -> release/0.0.2
A109: ms-sys-legal-entity-directory-pe-v1 | B109: =ISNUMBER(MATCH(A109,Inventario!D:D, 0)) -> 1 | C109: =IFERROR(INDEX(Inventario!O:O, MATCH(A109,Inventario!D:D, 0)), "") -> 1.0.2 | D109: =IFERROR(INDEX(Inventario!M:M, MATCH(A109, Inventario!D:D, 0)), "") -> http://repos.bancsabadell.com/bitbucket/scm/P4CP/ms-sys-legal-entity-directory-pe-v1.git | E109: =SUBSTITUTE(D109, ".git", "-conf/browse") -> http://repos.bancsabadell.com/bitbucket/scm/P4CP/ms-sys-legal-entity-directory-pe-v1-conf/browse | F109: =CONCATENATE("release/",C109) -> release/1.0.2
A110: ms-sys-party-reference-data-pe | B110: =ISNUMBER(MATCH(A110,Inventario!D:D, 0)) -> 1 | C110: =IFERROR(INDEX(Inventario!O:O, MATCH(A110,Inventario!D:D, 0)), "") -> 1.6.2 | D110: =IFERROR(INDEX(Inventario!M:M, MATCH(A110, Inventario!D:D, 0)), "") -> http://repos.bancsabadell.com/bitbucket/scm/P4CP/ms-sys-party-reference-data-pe.git | E110: =SUBSTITUTE(D110, ".git", "-conf/browse") -> http://repos.bancsabadell.com/bitbucket/scm/P4CP/ms-sys-party-reference-data-pe-conf/browse | F110: =CONCATENATE("release/",C110) -> release/1.6.2
A111: ms-sys-party-reference-data-pe-v2 | B111: =ISNUMBER(MATCH(A111,Inventario!D:D, 0)) -> 1 | C111: =IFERROR(INDEX(Inventario!O:O, MATCH(A111,Inventario!D:D, 0)), "") -> 1.0.6 | D111: =IFERROR(INDEX(Inventario!M:M, MATCH(A111, Inventario!D:D, 0)), "") -> http://repos.bancsabadell.com/bitbucket/scm/P4CP/ms-sys-party-reference-data-pe-v2.git | E111: =SUBSTITUTE(D111, ".git", "-conf/browse") -> http://repos.bancsabadell.com/bitbucket/scm/P4CP/ms-sys-party-reference-data-pe-v2-conf/browse | F111: =CONCATENATE("release/",C111) -> release/1.0.6
A112: ms-sys-party-reference-data-pe-v3 | B112: =ISNUMBER(MATCH(A112,Inventario!D:D, 0)) -> 1 | C112: =IFERROR(INDEX(Inventario!O:O, MATCH(A112,Inventario!D:D, 0)), "") -> 1.10.4 | D112: =IFERROR(INDEX(Inventario!M:M, MATCH(A112, Inventario!D:D, 0)), "") -> http://repos.bancsabadell.com/bitbucket/scm/MOBI/ms-sys-party-reference-data-pe-v3.git | E112: =SUBSTITUTE(D112, ".git", "-conf/browse") -> http://repos.bancsabadell.com/bitbucket/scm/MOBI/ms-sys-party-reference-data-pe-v3-conf/browse | F112: =CONCATENATE("release/",C112) -> release/1.10.4
A113: ms-sys-pe-connected-client | B113: =ISNUMBER(MATCH(A113,Inventario!D:D, 0)) -> 1 | C113: =IFERROR(INDEX(Inventario!O:O, MATCH(A113,Inventario!D:D, 0)), "") -> 1.0.0 | D113: =IFERROR(INDEX(Inventario!M:M, MATCH(A113, Inventario!D:D, 0)), "") -> http://repos.bancsabadell.com/bitbucket/scm/ESSABCONNECTEDCLIENT/ms-sys-pe-connected-client.git | E113: =SUBSTITUTE(D113, ".git", "-conf/browse") -> http://repos.bancsabadell.com/bitbucket/scm/ESSABCONNECTEDCLIENT/ms-sys-pe-connected-client-conf/browse | F113: =CONCATENATE("release/",C113) -> release/1.0.0
A114: ms-sys-product-directory-kc | B114: =ISNUMBER(MATCH(A114,Inventario!D:D, 0)) -> 1 | C114: =IFERROR(INDEX(Inventario!O:O, MATCH(A114,Inventario!D:D, 0)), "") -> 1.0.1 | D114: =IFERROR(INDEX(Inventario!M:M, MATCH(A114, Inventario!D:D, 0)), "") -> http://repos.bancsabadell.com/bitbucket/scm/POOJJ/ms-sys-product-directory-kc.git | E114: =SUBSTITUTE(D114, ".git", "-conf/browse") -> http://repos.bancsabadell.com/bitbucket/scm/POOJJ/ms-sys-product-directory-kc-conf/browse | F114: =CONCATENATE("release/",C114) -> release/1.0.1
A115: ms-sys-public-reference-data-management-dv | B115: =ISNUMBER(MATCH(A115,Inventario!D:D, 0)) -> 1 | C115: =IFERROR(INDEX(Inventario!O:O, MATCH(A115,Inventario!D:D, 0)), "") -> 1.0.5 | D115: =IFERROR(INDEX(Inventario!M:M, MATCH(A115, Inventario!D:D, 0)), "") -> http://repos.bancsabadell.com/bitbucket/scm/P4CP/ms-sys-public-reference-data-management-dv.git | E115: =SUBSTITUTE(D115, ".git", "-conf/browse") -> http://repos.bancsabadell.com/bitbucket/scm/P4CP/ms-sys-public-reference-data-management-dv-conf/browse | F115: =CONCATENATE("release/",C115) -> release/1.0.5
A116: ms-baas-legal-entity-directory-pe-v1 | B116: =ISNUMBER(MATCH(A116,Inventario!D:D, 0)) -> 1 | C116: =IFERROR(INDEX(Inventario!O:O, MATCH(A116,Inventario!D:D, 0)), "") -> 0.1.3 | D116: =IFERROR(INDEX(Inventario!M:M, MATCH(A116, Inventario!D:D, 0)), "") -> http://repos.bancsabadell.com/bitbucket/scm/mobi/ms-baas-legal-entity-directory-pe-v1.git | E116: =SUBSTITUTE(D116, ".git", "-conf/browse") -> http://repos.bancsabadell.com/bitbucket/scm/mobi/ms-baas-legal-entity-directory-pe-v1-conf/browse | F116: =CONCATENATE("release/",C116) -> release/0.1.3
A117: ms-batch-connected-client | B117: =ISNUMBER(MATCH(A117,Inventario!D:D, 0)) -> 1 | C117: =IFERROR(INDEX(Inventario!O:O, MATCH(A117,Inventario!D:D, 0)), "") -> 1.0.3 | D117: =IFERROR(INDEX(Inventario!M:M, MATCH(A117, Inventario!D:D, 0)), "") -> http://repos.bancsabadell.com/bitbucket/scm/ESSABCONNECTEDCLIENT/ms-batch-connected-client.git | E117: =SUBSTITUTE(D117, ".git", "-conf/browse") -> http://repos.bancsabadell.com/bitbucket/scm/ESSABCONNECTEDCLIENT/ms-batch-connected-client-conf/browse | F117: =CONCATENATE("release/",C117) -> release/1.0.3
A118: ms-batch-informa-docu-pe | B118: =ISNUMBER(MATCH(A118,Inventario!D:D, 0)) -> 1 | C118: =IFERROR(INDEX(Inventario!O:O, MATCH(A118,Inventario!D:D, 0)), "") -> 2.0.4 | D118: =IFERROR(INDEX(Inventario!M:M, MATCH(A118, Inventario!D:D, 0)), "") -> http://repos.bancsabadell.com/bitbucket/scm/INFO/ms-batch-informa-docu-pe.git | E118: =SUBSTITUTE(D118, ".git", "-conf/browse") -> http://repos.bancsabadell.com/bitbucket/scm/INFO/ms-batch-informa-docu-pe-conf/browse | F118: =CONCATENATE("release/",C118) -> release/2.0.4
...

Sheet salidabranches-micros
A1: service | B1: url | C1: http_code | D1: branch | E1: status | F1: property_key | G1: property_value | H1: presente globales sys | I1: value en sys | J1: presente globales baas | K1: value en baas | L1: presente globales bff | M1: value en bff
A2: ms-baas-consumer-loan-v1 | B2: http://repos.bancsabadell.com/bitbucket/rest/api/1.0/projects/P4CP/repos/ms-baas-consumer-loan-v1-conf/browse/pro/configs/application.yaml?at=release/1.3.3 | C2: 404 | D2: release/1.3.3 | E2: 404 | H2: =ISNUMBER(MATCH(F2,'globales-sys'!F:F, 0)) -> FALSE | I2: =IFERROR(INDEX('globales-sys'!G:G, MATCH(F2,'globales-sys'!F:F, 0)), "") | J2: =ISNUMBER(MATCH(F2,'globales-baas'!F:F, 0)) -> FALSE | K2: =IFERROR(INDEX('globales-baas'!G:G, MATCH(F2,'globales-baas'!F:F, 0)), "") | L2: =ISNUMBER(MATCH(F2,'globales-bff'!F:F, 0)) -> FALSE | M2: =IFERROR(INDEX('globales-bff'!G:G, MATCH(F2,'globales-bff'!F:F, 0)), "")
A3: ms-batch-sinfonia-processor | B3: http://repos.bancsabadell.com/bitbucket/rest/api/1.0/projects/p4cp/repos/ms-batch-sinfonia-processor-conf/browse/pro/configs/application.yaml?at=release/1.0.7 | C3: 404 | D3: release/1.0.7 | E3: 404 | H3: =ISNUMBER(MATCH(F3,'globales-sys'!F:F, 0)) -> FALSE | I3: =IFERROR(INDEX('globales-sys'!G:G, MATCH(F3,'globales-sys'!F:F, 0)), "") | J3: =ISNUMBER(MATCH(F3,'globales-baas'!F:F, 0)) -> FALSE | K3: =IFERROR(INDEX('globales-baas'!G:G, MATCH(F3,'globales-baas'!F:F, 0)), "") | L3: =ISNUMBER(MATCH(F3,'globales-bff'!F:F, 0)) -> FALSE | M3: =IFERROR(INDEX('globales-bff'!G:G, MATCH(F3,'globales-bff'!F:F, 0)), "")
A4: ms-baas-special-pricing-conditions | B4: http://repos.bancsabadell.com/bitbucket/rest/api/1.0/projects/JUST_RAROC/repos/ms-baas-special-pricing-conditions-conf/browse/pro/configs/application.yaml?at=release/0.8.19 | C4: 404 | D4: release/0.8.19 | E4: 404 | H4: =ISNUMBER(MATCH(F4,'globales-sys'!F:F, 0)) -> FALSE | I4: =IFERROR(INDEX('globales-sys'!G:G, MATCH(F4,'globales-sys'!F:F, 0)), "") | J4: =ISNUMBER(MATCH(F4,'globales-baas'!F:F, 0)) -> FALSE | K4: =IFERROR(INDEX('globales-baas'!G:G, MATCH(F4,'globales-baas'!F:F, 0)), "") | L4: =ISNUMBER(MATCH(F4,'globales-bff'!F:F, 0)) -> FALSE | M4: =IFERROR(INDEX('globales-bff'!G:G, MATCH(F4,'globales-bff'!F:F, 0)), "")
A5: ms-sys-credit-facility-online-pr | B5: http://repos.bancsabadell.com/bitbucket/rest/api/1.0/projects/P4CP/repos/ms-sys-credit-facility-online-pr-conf/browse/pro/configs/application.yaml?at=release/1.0.2 | C5: 404 | D5: release/1.0.2 | E5: 404 | H5: =ISNUMBER(MATCH(F5,'globales-sys'!F:F, 0)) -> FALSE | I5: =IFERROR(INDEX('globales-sys'!G:G, MATCH(F5,'globales-sys'!F:F, 0)), "") | J5: =ISNUMBER(MATCH(F5,'globales-baas'!F:F, 0)) -> FALSE | K5: =IFERROR(INDEX('globales-baas'!G:G, MATCH(F5,'globales-baas'!F:F, 0)), "") | L5: =ISNUMBER(MATCH(F5,'globales-bff'!F:F, 0)) -> FALSE | M5: =IFERROR(INDEX('globales-bff'!G:G, MATCH(F5,'globales-bff'!F:F, 0)), "")
A6: ms-baas-scf-packaging | B6: http://repos.bancsabadell.com/bitbucket/rest/api/1.0/projects/p4cp/repos/ms-baas-scf-packaging-conf/browse/pro/configs/application.yaml?at=release/1.0.6 | C6: 200 | D6: release/1.0.6 | E6: OK | F6: proteo4.domain-client.services[0].base-url | G6: https://ms-sys-party-reference-data-pe-pro-ns-sys.apps.pro.aws.bancsabadell.com | H6: =ISNUMBER(MATCH(F6,'globales-sys'!F:F, 0)) -> FALSE | I6: =IFERROR(INDEX('globales-sys'!G:G, MATCH(F6,'globales-sys'!F:F, 0)), "") | J6: =ISNUMBER(MATCH(F6,'globales-baas'!F:F, 0)) -> FALSE | K6: =IFERROR(INDEX('globales-baas'!G:G, MATCH(F6,'globales-baas'!F:F, 0)), "") | L6: =ISNUMBER(MATCH(F6,'globales-bff'!F:F, 0)) -> FALSE | M6: =IFERROR(INDEX('globales-bff'!G:G, MATCH(F6,'globales-bff'!F:F, 0)), "")
A7: ms-baas-scf-packaging | B7: http://repos.bancsabadell.com/bitbucket/rest/api/1.0/projects/p4cp/repos/ms-baas-scf-packaging-conf/browse/pro/configs/application.yaml?at=release/1.0.6 | C7: 200 | D7: release/1.0.6 | E7: OK | F7: proteo4.domain-client.services[1].base-url | G7: https://ms-sys-party-reference-data-pe-v2-pro-ns-sys.apps.pro.aws.bancsabadell.com | H7: =ISNUMBER(MATCH(F7,'globales-sys'!F:F, 0)) -> FALSE | I7: =IFERROR(INDEX('globales-sys'!G:G, MATCH(F7,'globales-sys'!F:F, 0)), "") | J7: =ISNUMBER(MATCH(F7,'globales-baas'!F:F, 0)) -> FALSE | K7: =IFERROR(INDEX('globales-baas'!G:G, MATCH(F7,'globales-baas'!F:F, 0)), "") | L7: =ISNUMBER(MATCH(F7,'globales-bff'!F:F, 0)) -> FALSE | M7: =IFERROR(INDEX('globales-bff'!G:G, MATCH(F7,'globales-bff'!F:F, 0)), "")
A8: ms-baas-scf-packaging | B8: http://repos.bancsabadell.com/bitbucket/rest/api/1.0/projects/p4cp/repos/ms-baas-scf-packaging-conf/browse/pro/configs/application.yaml?at=release/1.0.6 | C8: 200 | D8: release/1.0.6 | E8: OK | F8: proteo4.domain-client.services[2].base-url | G8: https://ms-sys-legal-entity-directory-ee-v1-pro-ns-sys.apps.pro.aws.bancsabadell.com | H8: =ISNUMBER(MATCH(F8,'globales-sys'!F:F, 0)) -> FALSE | I8: =IFERROR(INDEX('globales-sys'!G:G, MATCH(F8,'globales-sys'!F:F, 0)), "") | J8: =ISNUMBER(MATCH(F8,'globales-baas'!F:F, 0)) -> FALSE | K8: =IFERROR(INDEX('globales-baas'!G:G, MATCH(F8,'globales-baas'!F:F, 0)), "") | L8: =ISNUMBER(MATCH(F8,'globales-bff'!F:F, 0)) -> FALSE | M8: =IFERROR(INDEX('globales-bff'!G:G, MATCH(F8,'globales-bff'!F:F, 0)), "")
A9: ms-baas-scf-packaging | B9: http://repos.bancsabadell.com/bitbucket/rest/api/1.0/projects/p4cp/repos/ms-baas-scf-packaging-conf/browse/pro/configs/application.yaml?at=release/1.0.6 | C9: 200 | D9: release/1.0.6 | E9: OK | F9: proteo4.domain-client.services[3].base-url | G9: https://ms-sys-consumer-loan-scf-pro-ns-sys.apps.pro.aws.bancsabadell.com | H9: =ISNUMBER(MATCH(F9,'globales-sys'!F:F, 0)) -> FALSE | I9: =IFERROR(INDEX('globales-sys'!G:G, MATCH(F9,'globales-sys'!F:F, 0)), "") | J9: =ISNUMBER(MATCH(F9,'globales-baas'!F:F, 0)) -> FALSE | K9: =IFERROR(INDEX('globales-baas'!G:G, MATCH(F9,'globales-baas'!F:F, 0)), "") | L9: =ISNUMBER(MATCH(F9,'globales-bff'!F:F, 0)) -> FALSE | M9: =IFERROR(INDEX('globales-bff'!G:G, MATCH(F9,'globales-bff'!F:F, 0)), "")
A10: ms-baas-scf-packaging | B10: http://repos.bancsabadell.com/bitbucket/rest/api/1.0/projects/p4cp/repos/ms-baas-scf-packaging-conf/browse/pro/configs/application.yaml?at=release/1.0.6 | C10: 200 | D10: release/1.0.6 | E10: OK | F10: proteo4.domain-client.services[4].base-url | G10: https://ms-sys-customer-relationship-management-scf-pro-ns-sys.apps.pro.aws.bancsabadell.com | H10: =ISNUMBER(MATCH(F10,'globales-sys'!F:F, 0)) -> FALSE | I10: =IFERROR(INDEX('globales-sys'!G:G, MATCH(F10,'globales-sys'!F:F, 0)), "") | J10: =ISNUMBER(MATCH(F10,'globales-baas'!F:F, 0)) -> FALSE | K10: =IFERROR(INDEX('globales-baas'!G:G, MATCH(F10,'globales-baas'!F:F, 0)), "") | L10: =ISNUMBER(MATCH(F10,'globales-bff'!F:F, 0)) -> FALSE | M10: =IFERROR(INDEX('globales-bff'!G:G, MATCH(F10,'globales-bff'!F:F, 0)), "")
A11: ms-baas-scf-packaging | B11: http://repos.bancsabadell.com/bitbucket/rest/api/1.0/projects/p4cp/repos/ms-baas-scf-packaging-conf/browse/pro/configs/application.yaml?at=release/1.0.6 | C11: 200 | D11: release/1.0.6 | E11: OK | F11: proteo4.domain-client.services[5].base-url | G11: https://ms-sys-card-terminal-operation-ps-pro-ns-sys.apps.pro.aws.bancsabadell.com | H11: =ISNUMBER(MATCH(F11,'globales-sys'!F:F, 0)) -> FALSE | I11: =IFERROR(INDEX('globales-sys'!G:G, MATCH(F11,'globales-sys'!F:F, 0)), "") | J11: =ISNUMBER(MATCH(F11,'globales-baas'!F:F, 0)) -> FALSE | K11: =IFERROR(INDEX('globales-baas'!G:G, MATCH(F11,'globales-baas'!F:F, 0)), "") | L11: =ISNUMBER(MATCH(F11,'globales-bff'!F:F, 0)) -> FALSE | M11: =IFERROR(INDEX('globales-bff'!G:G, MATCH(F11,'globales-bff'!F:F, 0)), "")
A12: ms-baas-scf-packaging | B12: http://repos.bancsabadell.com/bitbucket/rest/api/1.0/projects/p4cp/repos/ms-baas-scf-packaging-conf/browse/pro/configs/application.yaml?at=release/1.0.6 | C12: 200 | D12: release/1.0.6 | E12: OK | F12: proteo4.domain-client.services[6].base-url | G12: https://ms-sys-customer-campaign-execution-system-kx-pro-ns-sys.apps.pro.aws.bancsabadell.com | H12: =ISNUMBER(MATCH(F12,'globales-sys'!F:F, 0)) -> FALSE | I12: =IFERROR(INDEX('globales-sys'!G:G, MATCH(F12,'globales-sys'!F:F, 0)), "") | J12: =ISNUMBER(MATCH(F12,'globales-baas'!F:F, 0)) -> FALSE | K12: =IFERROR(INDEX('globales-baas'!G:G, MATCH(F12,'globales-baas'!F:F, 0)), "") | L12: =ISNUMBER(MATCH(F12,'globales-bff'!F:F, 0)) -> FALSE | M12: =IFERROR(INDEX('globales-bff'!G:G, MATCH(F12,'globales-bff'!F:F, 0)), "")
A13: ms-baas-scf-packaging | B13: http://repos.bancsabadell.com/bitbucket/rest/api/1.0/projects/p4cp/repos/ms-baas-scf-packaging-conf/browse/pro/configs/application.yaml?at=release/1.0.6 | C13: 200 | D13: release/1.0.6 | E13: OK | F13: proteo4.domain-client.services[7].base-url | G13: https://ms-sys-legal-entity-directory-pe-v1-pro-ns-sys.apps.pro.aws.bancsabadell.com | H13: =ISNUMBER(MATCH(F13,'globales-sys'!F:F, 0)) -> FALSE | I13: =IFERROR(INDEX('globales-sys'!G:G, MATCH(F13,'globales-sys'!F:F, 0)), "") | J13: =ISNUMBER(MATCH(F13,'globales-baas'!F:F, 0)) -> FALSE | K13: =IFERROR(INDEX('globales-baas'!G:G, MATCH(F13,'globales-baas'!F:F, 0)), "") | L13: =ISNUMBER(MATCH(F13,'globales-bff'!F:F, 0)) -> FALSE | M13: =IFERROR(INDEX('globales-bff'!G:G, MATCH(F13,'globales-bff'!F:F, 0)), "")
A14: ms-baas-scf-packaging | B14: http://repos.bancsabadell.com/bitbucket/rest/api/1.0/projects/p4cp/repos/ms-baas-scf-packaging-conf/browse/pro/configs/application.yaml?at=release/1.0.6 | C14: 200 | D14: release/1.0.6 | E14: OK | F14: proteo4.domain-client.services[8].base-url | G14: https://ms-sys-sales-product-agreement-system-pe-v1-pro-ns-sys.apps.pro.aws.bancsabadell.com | H14: =ISNUMBER(MATCH(F14,'globales-sys'!F:F, 0)) -> FALSE | I14: =IFERROR(INDEX('globales-sys'!G:G, MATCH(F14,'globales-sys'!F:F, 0)), "") | J14: =ISNUMBER(MATCH(F14,'globales-baas'!F:F, 0)) -> FALSE | K14: =IFERROR(INDEX('globales-baas'!G:G, MATCH(F14,'globales-baas'!F:F, 0)), "") | L14: =ISNUMBER(MATCH(F14,'globales-bff'!F:F, 0)) -> FALSE | M14: =IFERROR(INDEX('globales-bff'!G:G, MATCH(F14,'globales-bff'!F:F, 0)), "")
A15: ms-sys-card-terminal-operation-ps | B15: http://repos.bancsabadell.com/bitbucket/rest/api/1.0/projects/P4CP/repos/ms-sys-card-terminal-operation-ps-conf/browse/pro/configs/application.yaml?at=release/1.0.2 | C15: 200 | D15: release/1.0.2 | E15: OK | F15: proteo4.error-literal.baseUrl | G15: https://ms-infra-literal-adapter-pro-ns-inf.apps.pro.aws.bancsabadell.com | H15: =ISNUMBER(MATCH(F15,'globales-sys'!F:F, 0)) -> FALSE | I15: =IFERROR(INDEX('globales-sys'!G:G, MATCH(F15,'globales-sys'!F:F, 0)), "") | J15: =ISNUMBER(MATCH(F15,'globales-baas'!F:F, 0)) -> FALSE | K15: =IFERROR(INDEX('globales-baas'!G:G, MATCH(F15,'globales-baas'!F:F, 0)), "") | L15: =ISNUMBER(MATCH(F15,'globales-bff'!F:F, 0)) -> FALSE | M15: =IFERROR(INDEX('globales-bff'!G:G, MATCH(F15,'globales-bff'!F:F, 0)), "")
A16: ms-sys-card-terminal-operation-ps | B16: http://repos.bancsabadell.com/bitbucket/rest/api/1.0/projects/P4CP/repos/ms-sys-card-terminal-operation-ps-conf/browse/pro/configs/application.yaml?at=release/1.0.2 | C16: 200 | D16: release/1.0.2 | E16: OK | F16: proteo4.mainframe-adapter.base-url | G16: https://ms-infra-mainframe-adapter-pro-ns-inf.apps.pro.aws.bancsabadell.com | H16: =ISNUMBER(MATCH(F16,'globales-sys'!F:F, 0)) -> TRUE | I16: =IFERROR(INDEX('globales-sys'!G:G, MATCH(F16,'globales-sys'!F:F, 0)), "") -> https://ms-infra-mainframe-adapter-pro-ns-inf.${PROVIDER_SUFFIX_URL:apps.pro.aws.bancsabadell.com} | J16: =ISNUMBER(MATCH(F16,'globales-baas'!F:F, 0)) -> FALSE | K16: =IFERROR(INDEX('globales-baas'!G:G, MATCH(F16,'globales-baas'!F:F, 0)), "") | L16: =ISNUMBER(MATCH(F16,'globales-bff'!F:F, 0)) -> FALSE | M16: =IFERROR(INDEX('globales-bff'!G:G, MATCH(F16,'globales-bff'!F:F, 0)), "")
A17: ms-sys-customer-campaign-execution-system-kx | B17: http://repos.bancsabadell.com/bitbucket/rest/api/1.0/projects/P4CP/repos/ms-sys-customer-campaign-execution-system-kx-conf/browse/pro/configs/application.yaml?at=release/1.0.2 | C17: 200 | D17: release/1.0.2 | E17: OK | F17: proteo4.error-literal.baseUrl | G17: https://ms-infra-literal-adapter-pro-ns-inf.apps.pro.aws.bancsabadell.com | H17: =ISNUMBER(MATCH(F17,'globales-sys'!F:F, 0)) -> FALSE | I17: =IFERROR(INDEX('globales-sys'!G:G, MATCH(F17,'globales-sys'!F:F, 0)), "") | J17: =ISNUMBER(MATCH(F17,'globales-baas'!F:F, 0)) -> FALSE | K17: =IFERROR(INDEX('globales-baas'!G:G, MATCH(F17,'globales-baas'!F:F, 0)), "") | L17: =ISNUMBER(MATCH(F17,'globales-bff'!F:F, 0)) -> FALSE | M17: =IFERROR(INDEX('globales-bff'!G:G, MATCH(F17,'globales-bff'!F:F, 0)), "")
A18: ms-sys-customer-campaign-execution-system-kx | B18: http://repos.bancsabadell.com/bitbucket/rest/api/1.0/projects/P4CP/repos/ms-sys-customer-campaign-execution-system-kx-conf/browse/pro/configs/application.yaml?at=release/1.0.2 | C18: 200 | D18: release/1.0.2 | E18: OK | F18: proteo4.mainframe-adapter.base-url | G18: https://ms-infra-mainframe-adapter-pro-ns-inf.apps.pro.aws.bancsabadell.com | H18: =ISNUMBER(MATCH(F18,'globales-sys'!F:F, 0)) -> TRUE | I18: =IFERROR(INDEX('globales-sys'!G:G, MATCH(F18,'globales-sys'!F:F, 0)), "") -> https://ms-infra-mainframe-adapter-pro-ns-inf.${PROVIDER_SUFFIX_URL:apps.pro.aws.bancsabadell.com} | J18: =ISNUMBER(MATCH(F18,'globales-baas'!F:F, 0)) -> FALSE | K18: =IFERROR(INDEX('globales-baas'!G:G, MATCH(F18,'globales-baas'!F:F, 0)), "") | L18: =ISNUMBER(MATCH(F18,'globales-bff'!F:F, 0)) -> FALSE | M18: =IFERROR(INDEX('globales-bff'!G:G, MATCH(F18,'globales-bff'!F:F, 0)), "")
A19: ms-baas-factoring-v1 | B19: http://repos.bancsabadell.com/bitbucket/rest/api/1.0/projects/P4cp/repos/ms-baas-factoring-v1-conf/browse/pro/configs/application.yaml?at=release/1.0.6 | C19: 404 | D19: release/1.0.6 | E19: 404 | H19: =ISNUMBER(MATCH(F19,'globales-sys'!F:F, 0)) -> FALSE | I19: =IFERROR(INDEX('globales-sys'!G:G, MATCH(F19,'globales-sys'!F:F, 0)), "") | J19: =ISNUMBER(MATCH(F19,'globales-baas'!F:F, 0)) -> FALSE | K19: =IFERROR(INDEX('globales-baas'!G:G, MATCH(F19,'globales-baas'!F:F, 0)), "") | L19: =ISNUMBER(MATCH(F19,'globales-bff'!F:F, 0)) -> FALSE | M19: =IFERROR(INDEX('globales-bff'!G:G, MATCH(F19,'globales-bff'!F:F, 0)), "")
A20: ms-sys-factoring-system-fa-v1 | B20: http://repos.bancsabadell.com/bitbucket/rest/api/1.0/projects/P4cp/repos/ms-sys-factoring-system-fa-v1-conf/browse/pro/configs/application.yaml?at=release/1.0.6 | C20: 404 | D20: release/1.0.6 | E20: 404 | H20: =ISNUMBER(MATCH(F20,'globales-sys'!F:F, 0)) -> FALSE | I20: =IFERROR(INDEX('globales-sys'!G:G, MATCH(F20,'globales-sys'!F:F, 0)), "") | J20: =ISNUMBER(MATCH(F20,'globales-baas'!F:F, 0)) -> FALSE | K20: =IFERROR(INDEX('globales-baas'!G:G, MATCH(F20,'globales-baas'!F:F, 0)), "") | L20: =ISNUMBER(MATCH(F20,'globales-bff'!F:F, 0)) -> FALSE | M20: =IFERROR(INDEX('globales-bff'!G:G, MATCH(F20,'globales-bff'!F:F, 0)), "")
A21: ms-sys-confirming-kf-v1 | B21: http://repos.bancsabadell.com/bitbucket/rest/api/1.0/projects/p4cp/repos/ms-sys-confirming-kf-v1-conf/browse/pro/configs/application.yaml?at=release/1.0.8 | C21: 200 | D21: release/1.0.8 | E21: OK | F21: proteo4.file-storage-service-platform.base-url-uploadlink | G21: https://content.pro.aws.bancsabadell.com/private-document-library-storage/v1 | H21: =ISNUMBER(MATCH(F21,'globales-sys'!F:F, 0)) -> FALSE | I21: =IFERROR(INDEX('globales-sys'!G:G, MATCH(F21,'globales-sys'!F:F, 0)), "") | J21: =ISNUMBER(MATCH(F21,'globales-baas'!F:F, 0)) -> FALSE | K21: =IFERROR(INDEX('globales-baas'!G:G, MATCH(F21,'globales-baas'!F:F, 0)), "") | L21: =ISNUMBER(MATCH(F21,'globales-bff'!F:F, 0)) -> FALSE | M21: =IFERROR(INDEX('globales-bff'!G:G, MATCH(F21,'globales-bff'!F:F, 0)), "")
A22: ms-sys-xy-common-data | B22: http://repos.bancsabadell.com/bitbucket/rest/api/1.0/projects/P4CP/repos/ms-sys-xy-common-data-conf/browse/pro/configs/application.yaml?at=release/1.1.0 | C22: 200 | D22: release/1.1.0 | E22: OK | F22: proteo4.mainframe-adapter.base-url | G22: https://ms-infra-mainframe-adapter-pro-ns-inf.apps.pro.aws.bancsabadell.com | H22: =ISNUMBER(MATCH(F22,'globales-sys'!F:F, 0)) -> TRUE | I22: =IFERROR(INDEX('globales-sys'!G:G, MATCH(F22,'globales-sys'!F:F, 0)), "") -> https://ms-infra-mainframe-adapter-pro-ns-inf.${PROVIDER_SUFFIX_URL:apps.pro.aws.bancsabadell.com} | J22: =ISNUMBER(MATCH(F22,'globales-baas'!F:F, 0)) -> FALSE | K22: =IFERROR(INDEX('globales-baas'!G:G, MATCH(F22,'globales-baas'!F:F, 0)), "") | L22: =ISNUMBER(MATCH(F22,'globales-bff'!F:F, 0)) -> FALSE | M22: =IFERROR(INDEX('globales-bff'!G:G, MATCH(F22,'globales-bff'!F:F, 0)), "")
A23: ms-sys-consumer-loan-system-pr | B23: http://repos.bancsabadell.com/bitbucket/rest/api/1.0/projects/P4CP/repos/ms-sys-consumer-loan-system-pr-conf/browse/pro/configs/application.yaml?at=release/1.0.6 | C23: 404 | D23: release/1.0.6 | E23: 404 | H23: =ISNUMBER(MATCH(F23,'globales-sys'!F:F, 0)) -> FALSE | I23: =IFERROR(INDEX('globales-sys'!G:G, MATCH(F23,'globales-sys'!F:F, 0)), "") | J23: =ISNUMBER(MATCH(F23,'globales-baas'!F:F, 0)) -> FALSE | K23: =IFERROR(INDEX('globales-baas'!G:G, MATCH(F23,'globales-baas'!F:F, 0)), "") | L23: =ISNUMBER(MATCH(F23,'globales-bff'!F:F, 0)) -> FALSE | M23: =IFERROR(INDEX('globales-bff'!G:G, MATCH(F23,'globales-bff'!F:F, 0)), "")
A24: ms-sys-factoring-inblock-v1 | B24: http://repos.bancsabadell.com/bitbucket/rest/api/1.0/projects/P4CP/repos/ms-sys-factoring-inblock-v1-conf/browse/pro/configs/application.yaml?at=release/1.2.5 | C24: 200 | D24: release/1.2.5 | E24: OK | F24: proteo4.file-storage-service-platform.base-url | G24: https://ms-storage-api-pro-ns-storage.apps.pro.aws.bancsabadell.com/private-document-library-storage/v1 | H24: =ISNUMBER(MATCH(F24,'globales-sys'!F:F, 0)) -> TRUE | I24: =IFERROR(INDEX('globales-sys'!G:G, MATCH(F24,'globales-sys'!F:F, 0)), "") -> https://ms-storage-api-pro-ns-inf.${PROVIDER_SUFFIX_URL:apps.pro.aws.bancsabadell.com}/private-document-library-storage/v1 | J24: =ISNUMBER(MATCH(F24,'globales-baas'!F:F, 0)) -> FALSE | K24: =IFERROR(INDEX('globales-baas'!G:G, MATCH(F24,'globales-baas'!F:F, 0)), "") | L24: =ISNUMBER(MATCH(F24,'globales-bff'!F:F, 0)) -> FALSE | M24: =IFERROR(INDEX('globales-bff'!G:G, MATCH(F24,'globales-bff'!F:F, 0)), "")
A25: ms-sys-factoring-inblock-v1 | B25: http://repos.bancsabadell.com/bitbucket/rest/api/1.0/projects/P4CP/repos/ms-sys-factoring-inblock-v1-conf/browse/pro/configs/application.yaml?at=release/1.2.5 | C25: 200 | D25: release/1.2.5 | E25: OK | F25: proteo4.file-storage-service-platform.base-url-uploadlink | G25: https://content.pro.aws.bancsabadell.com/private-document-library-storage/v1 | H25: =ISNUMBER(MATCH(F25,'globales-sys'!F:F, 0)) -> FALSE | I25: =IFERROR(INDEX('globales-sys'!G:G, MATCH(F25,'globales-sys'!F:F, 0)), "") | J25: =ISNUMBER(MATCH(F25,'globales-baas'!F:F, 0)) -> FALSE | K25: =IFERROR(INDEX('globales-baas'!G:G, MATCH(F25,'globales-baas'!F:F, 0)), "") | L25: =ISNUMBER(MATCH(F25,'globales-bff'!F:F, 0)) -> FALSE | M25: =IFERROR(INDEX('globales-bff'!G:G, MATCH(F25,'globales-bff'!F:F, 0)), "")
A26: ms-sys-factoring-inblock-v1 | B26: http://repos.bancsabadell.com/bitbucket/rest/api/1.0/projects/P4CP/repos/ms-sys-factoring-inblock-v1-conf/browse/pro/configs/application.yaml?at=release/1.2.5 | C26: 200 | D26: release/1.2.5 | E26: OK | F26: proteo4.netapp.clients[0].s3-settings.client.endpoint | G26: https://otm1.sgrid.es.bs/ | H26: =ISNUMBER(MATCH(F26,'globales-sys'!F:F, 0)) -> FALSE | I26: =IFERROR(INDEX('globales-sys'!G:G, MATCH(F26,'globales-sys'!F:F, 0)), "") | J26: =ISNUMBER(MATCH(F26,'globales-baas'!F:F, 0)) -> FALSE | K26: =IFERROR(INDEX('globales-baas'!G:G, MATCH(F26,'globales-baas'!F:F, 0)), "") | L26: =ISNUMBER(MATCH(F26,'globales-bff'!F:F, 0)) -> FALSE | M26: =IFERROR(INDEX('globales-bff'!G:G, MATCH(F26,'globales-bff'!F:F, 0)), "")
A27: ms-sys-factoring-inblock-v1 | B27: http://repos.bancsabadell.com/bitbucket/rest/api/1.0/projects/P4CP/repos/ms-sys-factoring-inblock-v1-conf/browse/pro/configs/application.yaml?at=release/1.2.5 | C27: 200 | D27: release/1.2.5 | E27: OK | F27: inblock.endpoints.base-url | G27: https://api.inblockaef.com/v1 | H27: =ISNUMBER(MATCH(F27,'globales-sys'!F:F, 0)) -> FALSE | I27: =IFERROR(INDEX('globales-sys'!G:G, MATCH(F27,'globales-sys'!F:F, 0)), "") | J27: =ISNUMBER(MATCH(F27,'globales-baas'!F:F, 0)) -> FALSE | K27: =IFERROR(INDEX('globales-baas'!G:G, MATCH(F27,'globales-baas'!F:F, 0)), "") | L27: =ISNUMBER(MATCH(F27,'globales-bff'!F:F, 0)) -> FALSE | M27: =IFERROR(INDEX('globales-bff'!G:G, MATCH(F27,'globales-bff'!F:F, 0)), "")
A28: ms-batch-inblock-upload | B28: http://repos.bancsabadell.com/bitbucket/rest/api/1.0/projects/P4CP/repos/ms-batch-inblock-upload-conf/browse/pro/configs/application.yaml?at=release/1.0.4 | C28: 200 | D28: release/1.0.4 | E28: OK | F28: proteo4.domain-client.services[0].base-url | G28: https://ms-sys-factoring-inblock-v1-pro-ns-sys.apps.pro.aws.bancsabadell.com | H28: =ISNUMBER(MATCH(F28,'globales-sys'!F:F, 0)) -> FALSE | I28: =IFERROR(INDEX('globales-sys'!G:G, MATCH(F28,'globales-sys'!F:F, 0)), "") | J28: =ISNUMBER(MATCH(F28,'globales-baas'!F:F, 0)) -> FALSE | K28: =IFERROR(INDEX('globales-baas'!G:G, MATCH(F28,'globales-baas'!F:F, 0)), "") | L28: =ISNUMBER(MATCH(F28,'globales-bff'!F:F, 0)) -> FALSE | M28: =IFERROR(INDEX('globales-bff'!G:G, MATCH(F28,'globales-bff'!F:F, 0)), "")
